---
icon: pen-to-square
date: 2024-07-26
category:
  - C++
tag:
  - C++
  - 异常处理

sticky: true
# 此页面会出现在星标文章中

order: 1
# 设置作者
author: Ms.Huang

---

# C++异常机制

## 1. C++异常机制概述

    C++的异常情况主要分为两种，一种是编译时的语法错误，另一种是运行时的异常，例如访问越界，内存不足等。异常机制专用于处理运行时异常。异常事件在C++中表示为异常对象，异常事件发生时，程序使用**throw**关键字抛出异常对象，抛出点称为异常出现点，由操作系统为程序设置当前异常类型，然后执行程序的当前异常处理代码块，在包含了异常出现点的最内层的try块，依次匹配catch语句中的异常对象。若匹配成功，则执行**catch**块内的异常处理语句，然后接着执行**try...catch...** 块之后的代码。如果在当前的try...catch...块内找不到匹配该异常对象的catch语句，则由更外层的try...catch...块来处理该异常；如果当前函数内所有的try...catch...块内找不到匹配该异常对象的catch语句，则由更外层的try...catch...块来处理该异常；如果当前函数内所有的try...catch...块都不能匹配该异常，则递归回退到调用栈的上一层去处理该异常。如果一直回退到主函数main()都不能处理该异常，则递归回退到调用栈的上一层处理该异常。如果一直回退到主函数main()都不能处理该异常，则调用系统函数**terminate()** 终止程序。



## 2. try、throw、catch

    throw与抛出表达式构成了throw语句，throw语句必须包含在try块中。如果在try语句块的程序段中（包括在其中调用的函数）发现了且抛出了该异常，则这个异常就可能被try语句块后的某个catch语句所捕获并处理，捕获和处理的条件是被抛出的异常对象的类型与catch语句的异常类型相匹配。

    catch语句匹配被抛出的异常对象，如果catch语句的参数是引用类型，则该参数可直接作用于异常对象，即参数的改变也会改变异常对象，而且在catch中重新抛出异常时会继续传递这种改变。如果catch参数是传值的，则复制构造函数依据异常对象来构造catch参数对象。在该catch语句结束的时候，先析构catch参数对象，然后再析构异常对象。

```cpp
try
{
    if(满足异常条件)
        throw 异常对象;    
}
catch(类型名 [形参名])    //捕获特定类型的异常
{

}
catch(类型名 [形参名])    //捕获特定类型的异常
{

}
catch(...)    //三个点表示捕获所有类型的异常
{

}
```

异常处理示例：处理除数为0的异常，用try/catch语句来捕获异常，并使用throw语句来抛出异常。

```cpp
#include<iostream>       
#include<cstdlib>
using namespace std;  

double func(double x, double y)
{  
    if(y == 0)  
    {  
        throw y;     //除数为0，抛出异常  
    }  
    return x / y;     //否则返回两个数的商  
}  

void main()  
{  
    double res;  
    try  //定义异常  
    {   
        res = fuc(4, 0);      //出现异常，函数内部会抛出异常  
    }  
    catch(double)             //捕获并处理异常  
    {  
         cerr << "error of dividing zero.\n";  
         exit(1);             //异常退出程序  
    }  
    cout << "The result of x / y is : " << res << endl;
}
```

## 3. C++标准异常

    C++标准库提供了一组异常类，用户可以在程序中使用这些标准的异常，也可以通过继承和重载exception类来定义新的异常。



下表是对每个标准异常类的简单说明：





| 异常                    | 描述                                                   |
| --------------------- | ---------------------------------------------------- |
| std::exception        | 该异常是所有标准 C++ 异常的父类                                   |
| std::bad_alloc        | 该异常可以通过 new 抛出                                       |
| std::bad_cast         | 该异常可以通过 dynamic_cast 抛出                              |
| std::bad_exception    | 这在处理 C++ 程序中无法预期的异常时非常有用                             |
| std::bad_typeid       | 该异常可以通过 typeid 抛出                                    |
| std::logic_error      | 理论上可以通过读取代码来检测到的异常                                   |
| std::domain_error     | 当使用了一个无效的数学域时，会抛出该异常                                 |
| std::invalid_argument | 当使用了无效的参数时，会抛出该异常                                    |
| std::length_error     | 当创建了太长的 std::string 时，会抛出该异常                         |
| std::out_of_range     | 该异常可以通过方法抛出，例如 std::vector 和 std::bitset<>::operator |
| std::runtime_error    | 理论上不可以通过读取代码来检测到的异常                                  |
| std::overflow_error   | 当发生数学上溢时，会抛出该异常                                      |
| std::range_error      | 当尝试存储超出范围的值时，会抛出该异常                                  |
| std::underflow_error  | 当发生数学下溢时，会抛出该异常                                      |

下面是通过继承和重载 exception 类来定义新异常类的简单示例：

```cpp
#include <iostream>
#include <exception>

class MyException : public std::exception
{
public:
    virtual const char *what() const noexcept override // what()是异常类提供的一个公共方法，它能被所有子异常类重载。
    {
        return "C++ Exception";
    }
};

int main()
{
    try
    {
        throw MyException();
    }
    catch (MyException &e)
    {
        std::cout << "MyException caught" << std::endl;
        std::cout << e.what() << std::endl;
    }
    catch (std::exception &e)
    {
        std::cout << e.what() << std::endl;
    }
}
```





## 4. 异常机制与构造函数

        构造函数没有返回值，应该使用异常机制来报告发生的问题。但构造函数抛出的异常表明构造函数没有执行完，不会生成特定的对象，对应的析构函数也不会自动被调用。因此在构造函数中抛出异常之前，需要先释放已经申请的资源。

```cpp
myClass::myClass(type t) try: val(初始化值)
{ 
    /*构造函数的函数体 */
} 
catch(exception& err) 
{
    /* 构造函数的异常处理部分 */ 
}
```

        C++不禁止析构函数向外界抛出异常，但一般来说析构函数不应该向外界函数抛出异常。析构函数中向外界抛出异常，将直接调用**terminator()** 系统函数终止程序。如果一个析构函数内部抛出了异常，就应该在析构函数的内部捕获并处理该异常，不能让异常抛出析构函数之外。可以如此处理：

* 若析构函数内部抛出异常，调用std::abort()来终止程序。、

* 在析构函数中catch捕获异常并作处理。（别让异常逃离析构函数）
  
  
  
  

## 5. 异常处理需要注意的问题

* 如果抛出的异常在这一层try...catch..中没有被捕获，则会栈展开（栈解退）逐层往上传递，直至回退到主函数main()都不能处理该异常，则调用系统函数terminate()终止程序。

* 一般在异常抛出后资源可以正常释放，但注意如果在类的构造函数中抛出异常，系统是不会调用它的析构函数的，处理方法是：在构造函数中抛出异常之前，先删除申请的资源。

* 异常处理仅仅通过类型而不是通过值来匹配，所有catch块的参数可以没有参数名称，只需要参数类型。

* 函数原型中的异常说明要与实现中的异常说明一致，否则容易引起异常冲突。

* 在利用throw语句抛出异常对象时，throw会先通过拷贝构造函数构造一个新对象，然后将新对象传递给catch参数。如果catch参数采用值传递，会再一次调用拷贝构造函数，给catch参数赋值；如果是引用（或传地址/指针），则无需赋值处理，这样不仅会提高效率，还可以利用对象的多态性。

* 异常抛出的新对象并非创建在函数栈上，而是创建在专用的异常栈上，因此它才可以跨接多个函数而传递到上层，当异常对象与catch语句成功匹配上后，在该catch语句的结束处被自动析构。所有从try到throw语句之间的局部对象的析构函数将被自动调用。但如果一直上溯到main函数后还没有找到匹配的catch块，那么系统调用terminate()终止整个程序，这种情况下不能保证所有局部对象会被正确地销毁。

* 派生类的异常捕获要放到父类异常扑获的前面，否则，派生类的异常无法被捕获。编写异常说明时，要确保派生类成员函数的异常说明和基类成员函数的异常说明一致，即派生类改写的虚函数的异常说明至少要和对应的基类虚函数的异常说明相同，甚至更加严格，更特殊。

* 在栈展开的过程中，会依次调用局部对象的析构函数释放资源。为了避免内存泄漏的情况，应该采用RAII机制（Resource acquisition is initialization，资源获取即初始化），即以对象管理资源，把资源数据用对象封装起来。程序发生异常，执行栈展开时，封装了资源的对象会自动调用其析构函数以释放资源。C++中的智能指针便符合RAII机制。
  
  

## 6. 相关函数

### 6.1 noexcept

`noexcept` 是 C++11 引入的一个关键字，用于指定一个函数是否会抛出异常。它的使用有助于明确函数的异常安全性，允许编译器进行更多优化，并帮助提高程序的稳定性。以下是 `noexcept` 的详细说明和使用方法：

**`noexcept` 的基本用法**

1. **标记函数不抛出异常**
   使用 `noexcept` 可以标记一个函数不会抛出任何异常。如果函数被标记为 `noexcept`，编译器可以优化代码，因为它知道这个函数不会抛出异常。

```cpp
void foo() noexcept; // 函数 foo 不会抛出异常
```



2. **`noexcept` 规范的参数**
   `noexcept` 可以接受一个布尔常量表达式作为参数，指示该函数是否会抛出异常：
   
   ```cpp
   void foo() noexcept(true);  // 表示 foo() 不会抛出异常
   void bar() noexcept(false); // 表示 bar() 可能会抛出异常
   ```
* `noexcept(true)` 或省略 `noexcept` 表示函数不会抛出异常。
* `noexcept(false)` 表示函数可能抛出异常。

**基本示例：**

```cpp
#include <iostream>

void foo() noexcept {
    std::cout << "foo() will not throw exceptions" << std::endl;
}

void bar() {
    std::cout << "bar() might throw exceptions" << std::endl;
}

int main() {
    foo(); // 这是安全的
    bar(); // 这也是安全的
    return 0;
}

```

**使用 `noexcept` 进行优化**

当 `noexcept` 用于标记不会抛出异常的函数时，编译器可以做出更有力的优化。例如，在使用标准库的容器时，若容器知道某些操作不会抛出异常，可能会做出更高效的实现。

```cpp
#include <vector>

void example() noexcept {
    std::vector<int> v;
    v.push_back(10); // 假设推送操作是 noexcept 的，编译器可以进行优化
}

```

**使用 `noexcept` 检查其他函数是否 noexcept**

C++11 引入了 `std::is_nothrow_invocable` 和 `std::is_nothrow_convertible` 类型特征，可以用来检查一个函数或表达式是否 `noexcept`：

```cpp
#include <iostream>
#include <type_traits>

void foo() noexcept {}

void bar() {}

int main() {
    std::cout << std::boolalpha;
    std::cout << "foo() noexcept: " << std::is_nothrow_invocable_v<decltype(foo)> << std::endl;
    std::cout << "bar() noexcept: " << std::is_nothrow_invocable_v<decltype(bar)> << std::endl;
    return 0;
}

```

**在 Lambda 表达式中使用 `noexcept`**

在 C++11 中，lambda 表达式可以通过 `noexcept` 指定是否会抛出异常：

```cpp
#include <iostream>

int main() {
    auto lambda_noexcept = []() noexcept {
        std::cout << "This lambda will not throw exceptions" << std::endl;
    };

    auto lambda_may_throw = []() {
        std::cout << "This lambda might throw exceptions" << std::endl;
    };

    lambda_noexcept();
    lambda_may_throw();

    return 0;
}

```

**与虚函数的兼容性**

当重写基类中的虚函数时，派生类中的函数也需要具有与基类函数相同的异常规范。例如：

```cpp
#include <iostream>
#include <exception>

class Base {
public:
    virtual void foo() noexcept = 0; // 纯虚函数，声明为 noexcept
};

class Derived : public Base {
public:
    void foo() noexcept override {
        std::cout << "Derived foo() noexcept" << std::endl;
    }
};

```

**总结** 

* **`noexcept`**：用于标记一个函数是否会抛出异常。如果一个函数被标记为 `noexcept`，编译器可以做出更有力的优化。
* **布尔常量**：`noexcept(true)` 表示函数不会抛出异常，`noexcept(false)` 表示函数可能抛出异常。
* **类型特征**：`std::is_nothrow_invocable` 和 `std::is_nothrow_convertible` 可用于检查函数是否 noexcept。

通过合理使用 `noexcept`，可以提高程序的性能和异常安全性，并使代码更易于理解和维护。





### 6.2 what()

在 C++ 中，`what()` 函数是 `std::exception` 类中的一个虚函数，用于提供关于异常的描述信息。它通常被用来获取异常的字符串描述，这对于错误处理和调试非常有用。下面将详细解释 `what()` 函数的定义、用法以及如何使用它来创建自定义异常类。

**1.`what()` 函数的定义**

`what()` 是 `std::exception` 类中的一个虚函数，定义如下：

```cpp
class std::exception {
public:
    virtual const char* what() const noexcept;
};

```

* **返回值**：`what()` 函数返回一个 `const char*` 类型的 C 风格字符串，这个字符串包含了异常的描述信息。
* **`noexcept`**：`what()` 函数被标记为 `noexcept`，表示它不会抛出异常。

**2.使用 `what()` 函数**

通常，你会通过捕获异常并调用 `what()` 函数来获取异常的描述信息

```cpp
#include <iostream>
#include <stdexcept>  // For std::exception

void mightThrow() {
    throw std::runtime_error("An error occurred in mightThrow");
}

int main() {
    try {
        mightThrow();
    } catch (const std::exception& e) {
        std::cerr << "Caught exception: " << e.what() << std::endl;
    }
    return 0;
}

```

在这个示例中，`std::runtime_error` 是一个标准异常类，它继承自 `std::exception` 并重写了 `what()` 函数。`e.what()` 会返回 "An error occurred in mightThrow" 字符串，该字符串描述了异常的原因。



**3.自定义异常类**

你可以创建自己的异常类，继承自 `std::exception` 或其派生类，并重写 `what()` 函数以提供自定义的错误信息。

```cpp
#include <iostream>
#include <exception>
#include <cstring>  // For std::strlen

class MyException : public std::exception {
private:
    const char* message;
public:
    explicit MyException(const char* msg) : message(msg) {}
    
    virtual const char* what() const noexcept override {
        return message;
    }
};

int main() {
    try {
        throw MyException("Custom exception message");
    } catch (const std::exception& e) {
        std::cerr << "Caught exception: " << e.what() << std::endl;
    }
    return 0;
}

```

在这个示例中，`MyException` 类继承自 `std::exception` 并重写了 `what()` 函数，以返回自定义的错误信息。

**4.关键点**

* **继承自 `std::exception`**：如果你需要定义自定义异常类，应当继承自 `std::exception` 或其子类，并重写 `what()` 函数。
* **`what()` 返回 C 风格字符串**：`what()` 函数返回的字符串是一个 C 风格字符串，你可以直接将其传递给输出流。
* **`noexcept` 说明**：`what()` 函数标记为 `noexcept`，这意味着它不应抛出异常，这在异常处理中很重要，避免了进一步的异常处理复杂性。

**总结**

`what()` 函数是 C++ 异常处理机制中的一个重要部分，它提供了一个标准化的方法来获取异常的描述信息。通过重写 `what()` 函数，你可以自定义异常的行为，使得异常信息更具描述性和针对性。这对于调试和错误处理非常有帮助。





### 6.3 cerr

cerr 是 C++ 标准库中的一个预定义对象，属于 `std::ostream` 类，用于将错误信息输出到标准错误设备（stderr）。它是 C++ 中处理错误输出的一种机制，与标准输出流 std::cout 相对应，但有着不同的特性和用途。以下是对 cerr 函数的详细解释：

**1.cerr 的定义与类型**

* **定义**：`std::cerr` 是 C++ 标准错误输出流，对应于 ISO C 标准库的 stderr。它是一个全局对象，用于将错误信息输出到标准错误设备。
* **类型**：`std::cerr` 是 `std::ostream` 类型的对象，因此它支持 `std::ostream` 类的所有成员函数和操作符，特别是 `<<` 操作符，用于向标准错误流中插入数据。

**2.cerr 的特性**

* **无缓冲**：默认情况下，cerr 的输出是不缓冲的。这意味着当使用 cerr 输出信息时，信息会立即被发送到标准错误设备，而不会被存储在缓冲区中等待后续输出。这一特性使得 cerr 非常适合用于输出紧急的、需要立即显示的信息，如错误消息。
* **与 cout 的同步**：虽然 cerr 默认是无缓冲的，但根据 ISO C++ 标准，cerr 被要求与 cout 同步。这意味着，在每次输出操作后，如果 cout 的缓冲区非空，cerr 会先强制刷新 cout 的缓冲区，然后再执行自己的输出操作。然而，这种同步行为可能会降低程序的性能，因此在实际应用中，如果不需要与 cout 同步，可以通过调用 `cerr.rdbuf()->pubsync()` 或 `cerr.rdbuf(0)` 来关闭同步。
* **不常被重定向**：与 cout 不同，cerr 通常不会被重定向到文件或其他输出目标。这是因为标准错误流通常用于显示对程序运行有重要影响的错误信息，这些信息应该直接显示在用户的控制台上，以便用户能够立即注意到并采取相应的措施。

**3.cerr 的使用场景**

cerr 通常用于输出错误信息和其他不属于正常逻辑的输出内容。例如，在程序执行过程中遇到无法恢复的错误时，可以使用 cerr 输出错误消息，以便用户了解发生了什么问题。此外，cerr 还可以用于输出警告信息或其他重要的、需要用户注意的信息。


